Workbook

Sheet Read Me
A1: Synthetic journal dataset for emotion-cause pair extraction (ECPE)
A3: What this is
A4: 100 synthetic journal-style entries (IDs S001 to S100) with draft labels, written by an LLM (Claude) in your two-sheet format.
A5: Use it for training and development. Do NOT use it as your final test set: LLM text is cleaner and more explicit than real journals, so scores on it will look inflated.
A7: Status of the labels
A8: All labels are LLM drafts (annotator = LLM-draft). A human must review them before they count as gold labels. Automatic checks already confirmed that every clause and entity is copied exactly from its entry and every label is from the fixed lists.
A10: Sheets
A11: Entries: one row per journal entry. Edit Text and the planned_ columns only before annotation starts. Columns G to I are formulas.
A12: Pairs: one row per emotion-cause pair. An entry with two pairs has two rows. The ner column is filled on the first row of each entry; later rows say same.
A13: Guidelines: the label lists and rules used to write these labels.
A14: Balance: live counts (formulas) of structures, emotions, aspects, lengths and entities against the plan. Blue numbers are the plan targets; change them if your plan changes.
A16: How to add your own human-written entries
A17: Add a row to Entries with a new ID (for example H001), Source = Human, and the whole entry in one cell. Add its pairs to Pairs using the same ID. The Balance sheet updates automatically (its ranges cover rows up to 500).

Sheet Entries
A1: ID | B1: Author | C1: Source | D1: Text | E1: planned_emotions | F1: planned_structure | G1: length_words | H1: length_bucket | I1: status
A2: S001 | B2: Claude (LLM) | C2: Synthetic | D2: Got my DBMS internal marks today and I scored 42 out of 50. Honestly so happy right now, I did not think I would cross 35. Even the lab viva went better than expected, finally some luck. | E2: joy | F2: cause before emotion | G2: =LEN(TRIM(D2))-LEN(SUBSTITUTE(TRIM(D2)," ",""))+1 -> 37 | H2: =IF(G2<40,"short",IF(G2<100,"medium",IF(G2<=200,"long","very long"))) -> short | I2: LLM-draft, needs human review
A3: S002 | B3: Claude (LLM) | C3: Synthetic | D3: My manager told us in the standup that the client loved our demo. Feeling really proud of the team, we worked on it for three weeks straight. Most of us skipped lunch on the last two days just to finish the slides. The meeting ran for almost an hour and the client asked for a second round next quarter. After the call we ordered pizza for the whole floor and the senior engineers stayed to go through the feedback line by line. I took notes on my laptop and then rewrote them in my diary at night because I did not trust myself to remember everything. | E3: pride | F3: cause before emotion | G3: =LEN(TRIM(D3))-LEN(SUBSTITUTE(TRIM(D3)," ",""))+1 -> 106 | H3: =IF(G3<40,"short",IF(G3<100,"medium",IF(G3<=200,"long","very long"))) -> long | I3: LLM-draft, needs human review
A4: S003 | B4: Claude (LLM) | C4: Synthetic | D4: Missed the 8:15 local by like ten seconds and had to wait 25 mins for the next one. So annoyed, ruined my whole morning. The next train was packed and I stood near the door the whole way with my bag on my chest. I reached the office twenty minutes late and had to sign the register at the gate. | E4: anger | F4: cause before emotion | G4: =LEN(TRIM(D4))-LEN(SUBSTITUTE(TRIM(D4)," ",""))+1 -> 60 | H4: =IF(G4<40,"short",IF(G4<100,"medium",IF(G4<=200,"long","very long"))) -> medium | I4: LLM-draft, needs human review
A5: S004 | B5: Claude (LLM) | C5: Synthetic | D5: Maa made my favourite rajma chawal after a really long week. I almost cried at the dinner table, so grateful for her. She does not say much but she always knows when I am tired. I helped her wash the dishes afterwards while she told me about the new shop near the temple. We watched half of a serial together and I fell asleep on the sofa with my head on a cushion. In the morning she had already packed a tiffin for me with extra pickle and two parathas for the bus. | E5: gratitude | F5: cause before emotion | G5: =LEN(TRIM(D5))-LEN(SUBSTITUTE(TRIM(D5)," ",""))+1 -> 93 | H5: =IF(G5<40,"short",IF(G5<100,"medium",IF(G5<=200,"long","very long"))) -> medium | I5: LLM-draft, needs human review
A6: S005 | B6: Claude (LLM) | C6: Synthetic | D6: Group project presentation went terrible, Aman forgot his entire part and I had to improvise. I was furious but did not say anything in front of everyone. Later he said sorry in the hallway but I just nodded and walked away. The slides had been finalised the night before and we had even rehearsed twice in the library. In the Q&A the panel asked about the second graph and I answered it while he stood there silently. After that we went to the canteen and split a plate of samosas without talking much. I took the long way back to the hostel. | E6: anger | F6: cause before emotion | G6: =LEN(TRIM(D6))-LEN(SUBSTITUTE(TRIM(D6)," ",""))+1 -> 102 | H6: =IF(G6<40,"short",IF(G6<100,"medium",IF(G6<=200,"long","very long"))) -> long | I6: LLM-draft, needs human review
A7: S006 | B7: Claude (LLM) | C7: Synthetic | D7: The assignment deadline is at 11 tonight and I have not even started the second question. So stressed right now. Tried to open the PDF three times and closed it each time, my brain just refuses. | E7: stress | F7: cause before emotion | G7: =LEN(TRIM(D7))-LEN(SUBSTITUTE(TRIM(D7)," ",""))+1 -> 36 | H7: =IF(G7<40,"short",IF(G7<100,"medium",IF(G7<=200,"long","very long"))) -> short | I7: LLM-draft, needs human review
A8: S007 | B8: Claude (LLM) | C8: Synthetic | D8: Neha texted me out of nowhere after like a year. I was so surprised to hear from her, we talked for almost two hours. She is studying in another city now and we caught up on college gossip, her new flat and the project she is working on. | E8: surprise | F8: cause before emotion | G8: =LEN(TRIM(D8))-LEN(SUBSTITUTE(TRIM(D8)," ",""))+1 -> 48 | H8: =IF(G8<40,"short",IF(G8<100,"medium",IF(G8<=200,"long","very long"))) -> medium | I8: LLM-draft, needs human review
A9: S008 | B9: Claude (LLM) | C9: Synthetic | D9: Failed the driving test for the second time because I stalled on the slope. I feel like such a loser. The marking sheet showed the same mistake as last time. I drove home slowly and parked outside the building for ten minutes before going in. | E9: sadness | F9: cause before emotion | G9: =LEN(TRIM(D9))-LEN(SUBSTITUTE(TRIM(D9)," ",""))+1 -> 45 | H9: =IF(G9<40,"short",IF(G9<100,"medium",IF(G9<=200,"long","very long"))) -> medium | I9: LLM-draft, needs human review
A10: S009 | B10: Claude (LLM) | C10: Synthetic | D10: Rohan borrowed my notes before the exam and gave them back with coffee stains all over. I am so stressed now, half the pages are unreadable and the test is tomorrow. He did not even say thanks, just dropped the notebook on my desk. I spent the next two hours in the library photocopying the same chapters from the shared drive printouts. The photocopy shop was crowded and the machine kept jamming, so I only got home at ten. I highlighted the main formulas in three colours and stuck them on the wall above my bed. Then I set two alarms and put my phone across the room. | E10: stress | F10: cause before emotion | G10: =LEN(TRIM(D10))-LEN(SUBSTITUTE(TRIM(D10)," ",""))+1 -> 108 | H10: =IF(G10<40,"short",IF(G10<100,"medium",IF(G10<=200,"long","very long"))) -> long | I10: LLM-draft, needs human review
A11: S010 | B11: Claude (LLM) | C11: Synthetic | D11: Dad called to say we are leaving for my cousin's wedding on Friday, for the whole week. Kind of dreading it, relatives will ask about placements again. I have a project review on Monday too and now I will have to skip it. The wedding hall is far from the city and we will be staying at a guest house for four nights. The bags are already by the door and the tickets are on my phone. I told the team that I would try to join the review online, but the signal there is usually bad. I packed my laptop and charger anyway, just in case. | E11: fear | F11: cause before emotion | G11: =LEN(TRIM(D11))-LEN(SUBSTITUTE(TRIM(D11)," ",""))+1 -> 107 | H11: =IF(G11<40,"short",IF(G11<100,"medium",IF(G11<=200,"long","very long"))) -> long | I11: LLM-draft, needs human review
A12: S011 | B12: Claude (LLM) | C12: Synthetic | D12: Our team won the inter-college quiz at COEP and I answered the last question. Proud of all of us, still smiling like an idiot. The final was between us and a team from the engineering college across the river, and it went down to a tiebreaker. We got a trophy and a voucher for a bookstore. We all took a group photo near the stage and then went for ice cream. | E12: pride | F12: cause before emotion | G12: =LEN(TRIM(D12))-LEN(SUBSTITUTE(TRIM(D12)," ",""))+1 -> 71 | H12: =IF(G12<40,"short",IF(G12<100,"medium",IF(G12<=200,"long","very long"))) -> medium | I12: LLM-draft, needs human review
A13: S012 | B13: Claude (LLM) | C13: Synthetic | D13: My phone fell off the bed and the screen cracked right across. Ugh so frustrated, I got it repaired only in April. I took it to a repair shop near the station on the same evening and left it there for the night. They quoted three thousand rupees for the screen replacement, and I paid half in advance. | E13: anger | F13: cause before emotion | G13: =LEN(TRIM(D13))-LEN(SUBSTITUTE(TRIM(D13)," ",""))+1 -> 58 | H13: =IF(G13<40,"short",IF(G13<100,"medium",IF(G13<=200,"long","very long"))) -> medium | I13: LLM-draft, needs human review
... A101: S100 | B101: Claude (LLM) | C101: Synthetic | D101: Reached the station at 6, boarded the 6:40 train to Nagpur with Raj and reached by noon. Slept most of the way. Had a vada pav at the station and then took an auto home. | E101: neutral | F101: no emotion | G101: =LEN(TRIM(D101))-LEN(SUBSTITUTE(TRIM(D101)," ",""))+1 -> 35 | H101: =IF(G101<40,"short",IF(G101<100,"medium",IF(G101<=200,"long","very long"))) -> short | I101: LLM-draft, needs human review

Sheet Pairs
A1: entry_id | B1: emotion_clause | C1: emotion | D1: cause_clause | E1: cause | F1: ner | G1: aspect | H1: annotator
A2: S001 | B2: Honestly so happy right now | C2: joy | D2: I scored 42 out of 50 | E2: good internal marks | F2: today|DATE | G2: studies_work | H2: LLM-draft
A3: S002 | B3: Feeling really proud of the team | C3: pride | D3: the client loved our demo | E3: client liked demo | F3: My manager|ROLE | G3: studies_work | H3: LLM-draft
A4: S003 | B4: So annoyed | C4: anger | D4: Missed the 8:15 local by like ten seconds | E4: missed train | F4: none | G4: other | H4: LLM-draft
A5: S004 | B5: so grateful for her | C5: gratitude | D5: Maa made my favourite rajma chawal after a really long week | E5: mother's cooking | F5: Maa|ROLE | G5: family | H5: LLM-draft
A6: S005 | B6: I was furious | C6: anger | D6: Aman forgot his entire part | E6: teammate forgot part | F6: Aman|PERSON | G6: studies_work | H6: LLM-draft
A7: S006 | B7: So stressed right now | C7: stress | D7: The assignment deadline is at 11 tonight and I have not even started the second question | E7: deadline | F7: tonight|DATE | G7: studies_work | H7: LLM-draft
A8: S007 | B8: I was so surprised to hear from her | C8: surprise | D8: Neha texted me out of nowhere after like a year | E8: old friend texted | F8: Neha|PERSON | G8: friends | H8: LLM-draft
A9: S008 | B9: I feel like such a loser | C9: sadness | D9: Failed the driving test for the second time because I stalled on the slope | E9: failed driving test | F9: none | G9: self | H9: LLM-draft
A10: S009 | B10: I am so stressed now | C10: stress | D10: Rohan borrowed my notes before the exam and gave them back with coffee stains all over | E10: notes damaged | F10: Rohan|PERSON; tomorrow|DATE | G10: studies_work | H10: LLM-draft
A11: S010 | B11: Kind of dreading it | C11: fear | D11: Dad called to say we are leaving for my cousin's wedding on Friday, for the whole week | E11: wedding trip | F11: Dad|ROLE; my cousin|ROLE; Friday|DATE; Monday|DATE | G11: family | H11: LLM-draft
A12: S011 | B12: Proud of all of us | C12: pride | D12: Our team won the inter-college quiz at COEP and I answered the last question | E12: won quiz | F12: COEP|ORG | G12: studies_work | H12: LLM-draft
... A116: S090 | B116: kind of proud when people clapped | C116: pride | D116: Had to give a surprise speech at Jai's farewell | E116: surprise speech | F116: same | G116: friends | H116: LLM-draft
A117: S091 | B117: Honestly feeling so grateful right now | C117: gratitude | E117: none | F117: none | G117: none | H117: LLM-draft
A118: S092 | B118: So angry right now | C118: anger | E118: none | F118: none | G118: none | H118: LLM-draft
A119: S093 | B119: Feeling a little anxious again today | C119: fear | E119: none | F119: today|DATE | G119: none | H119: LLM-draft
A120: S094 | B120: Just feeling really proud of myself | C120: pride | E120: none | F120: none | G120: none | H120: LLM-draft
A121: S095 | B121: Missing Nani so much | C121: sadness | E121: none | F121: Nani|ROLE | G121: none | H121: LLM-draft
A122: S096 | C122: neutral | E122: none | F122: Pune|LOCATION | G122: none | H122: LLM-draft
A123: S097 | C123: neutral | E123: none | F123: Today|DATE; Mom|ROLE | G123: none | H123: LLM-draft
A124: S098 | C124: neutral | E124: none | F124: COEP|ORG | G124: none | H124: LLM-draft
A125: S099 | C125: neutral | E125: none | F125: the plumber|ROLE; Thursday|DATE | G125: none | H125: LLM-draft
A126: S100 | C126: neutral | E126: none | F126: Raj|PERSON; Nagpur|LOCATION | G126: none | H126: LLM-draft

Sheet Balance
A1: Dataset balance (live formulas)
A2: Blue = plan targets you can edit. Black = formulas counting the Entries and Pairs sheets.
A4: Entry structure | B4: Target | C4: Actual | D4: Actual minus target
A5: cause before emotion | B5: 25 | C5: =COUNTIF(Entries!$F$2:$F$500,A5) -> 25 | D5: =C5-B5 -> 0
A6: cause after emotion | B6: 10 | C6: =COUNTIF(Entries!$F$2:$F$500,A6) -> 10 | D6: =C6-B6 -> 0
A7: different sentences | B7: 15 | C7: =COUNTIF(Entries!$F$2:$F$500,A7) -> 15 | D7: =C7-B7 -> 0
A8: implicit cause | B8: 15 | C8: =COUNTIF(Entries!$F$2:$F$500,A8) -> 15 | D8: =C8-B8 -> 0
A9: two emotions, two causes | B9: 20 | C9: =COUNTIF(Entries!$F$2:$F$500,A9) -> 20 | D9: =C9-B9 -> 0
A10: one cause, two emotions | B10: 5 | C10: =COUNTIF(Entries!$F$2:$F$500,A10) -> 5 | D10: =C10-B10 -> 0
A11: emotion only | B11: 5 | C11: =COUNTIF(Entries!$F$2:$F$500,A11) -> 5 | D11: =C11-B11 -> 0
A12: no emotion | B12: 5 | C12: =COUNTIF(Entries!$F$2:$F$500,A12) -> 5 | D12: =C12-B12 -> 0
A13: Total entries | B13: =SUM(B5:B12) -> 100 | C13: =SUM(C5:C12) -> 100 | D13: =C13-B13 -> 0
A15: Emotion (per pair row) | B15: Pair rows | C15: Share of rows
A16: joy | B16: =COUNTIF(Pairs!$C$2:$C$500,A16) -> 19 | C16: =IF(SUM($B$16:$B$26)=0,0,B16/SUM($B$16:$B$26)) -> 0.152
A17: contentment | B17: =COUNTIF(Pairs!$C$2:$C$500,A17) -> 8 | C17: =IF(SUM($B$16:$B$26)=0,0,B17/SUM($B$16:$B$26)) -> 0.064
A18: pride | B18: =COUNTIF(Pairs!$C$2:$C$500,A18) -> 13 | C18: =IF(SUM($B$16:$B$26)=0,0,B18/SUM($B$16:$B$26)) -> 0.104
A19: gratitude | B19: =COUNTIF(Pairs!$C$2:$C$500,A19) -> 8 | C19: =IF(SUM($B$16:$B$26)=0,0,B19/SUM($B$16:$B$26)) -> 0.064
A20: sadness | B20: =COUNTIF(Pairs!$C$2:$C$500,A20) -> 17 | C20: =IF(SUM($B$16:$B$26)=0,0,B20/SUM($B$16:$B$26)) -> 0.136
A21: anger | B21: =COUNTIF(Pairs!$C$2:$C$500,A21) -> 13 | C21: =IF(SUM($B$16:$B$26)=0,0,B21/SUM($B$16:$B$26)) -> 0.104
A22: fear | B22: =COUNTIF(Pairs!$C$2:$C$500,A22) -> 18 | C22: =IF(SUM($B$16:$B$26)=0,0,B22/SUM($B$16:$B$26)) -> 0.144
A23: stress | B23: =COUNTIF(Pairs!$C$2:$C$500,A23) -> 10 | C23: =IF(SUM($B$16:$B$26)=0,0,B23/SUM($B$16:$B$26)) -> 0.08
A24: guilt | B24: =COUNTIF(Pairs!$C$2:$C$500,A24) -> 7 | C24: =IF(SUM($B$16:$B$26)=0,0,B24/SUM($B$16:$B$26)) -> 0.056
A25: surprise | B25: =COUNTIF(Pairs!$C$2:$C$500,A25) -> 7 | C25: =IF(SUM($B$16:$B$26)=0,0,B25/SUM($B$16:$B$26)) -> 0.056
A26: neutral | B26: =COUNTIF(Pairs!$C$2:$C$500,A26) -> 5 | C26: =IF(SUM($B$16:$B$26)=0,0,B26/SUM($B$16:$B$26)) -> 0.04
A27: Total pair rows | B27: =SUM(B16:B26) -> 125
A29: Cause area (per pair row) | B29: Pair rows | C29: Share of rows
A30: studies_work | B30: =COUNTIF(Pairs!$G$2:$G$500,A30) -> 27 | C30: =IF(SUM($B$30:$B$38)=0,0,B30/SUM($B$30:$B$38)) -> 0.216
A31: health | B31: =COUNTIF(Pairs!$G$2:$G$500,A31) -> 7 | C31: =IF(SUM($B$30:$B$38)=0,0,B31/SUM($B$30:$B$38)) -> 0.056
A32: family | B32: =COUNTIF(Pairs!$G$2:$G$500,A32) -> 19 | C32: =IF(SUM($B$30:$B$38)=0,0,B32/SUM($B$30:$B$38)) -> 0.152
A33: friends | B33: =COUNTIF(Pairs!$G$2:$G$500,A33) -> 12 | C33: =IF(SUM($B$30:$B$38)=0,0,B33/SUM($B$30:$B$38)) -> 0.096
A34: relationships | B34: =COUNTIF(Pairs!$G$2:$G$500,A34) -> 7 | C34: =IF(SUM($B$30:$B$38)=0,0,B34/SUM($B$30:$B$38)) -> 0.056
A35: self | B35: =COUNTIF(Pairs!$G$2:$G$500,A35) -> 11 | C35: =IF(SUM($B$30:$B$38)=0,0,B35/SUM($B$30:$B$38)) -> 0.088
A36: money | B36: =COUNTIF(Pairs!$G$2:$G$500,A36) -> 6 | C36: =IF(SUM($B$30:$B$38)=0,0,B36/SUM($B$30:$B$38)) -> 0.048
A37: other | B37: =COUNTIF(Pairs!$G$2:$G$500,A37) -> 11 | C37: =IF(SUM($B$30:$B$38)=0,0,B37/SUM($B$30:$B$38)) -> 0.088
A38: none | B38: =COUNTIF(Pairs!$G$2:$G$500,A38) -> 25 | C38: =IF(SUM($B$30:$B$38)=0,0,B38/SUM($B$30:$B$38)) -> 0.2
A40: Entry length | B40: Target | C40: Actual | D40: Actual minus target
A41: short | B41: 20 | C41: =COUNTIF(Entries!$H$2:$H$500,A41) -> 35 | D41: =C41-B41 -> 15
A42: medium | B42: 50 | C42: =COUNTIF(Entries!$H$2:$H$500,A42) -> 46 | D42: =C42-B42 -> -4
A43: long | B43: 25 | C43: =COUNTIF(Entries!$H$2:$H$500,A43) -> 16 | D43: =C43-B43 -> -9
A44: very long | B44: 5 | C44: =COUNTIF(Entries!$H$2:$H$500,A44) -> 3 | D44: =C44-B44 -> -2
...

Sheet Guidelines
A1: Emotion labels (one label per emotion clause)
A2: label | B2: meaning | C2: example clause
A3: joy | B3: Happiness, excitement, being pleased | C3: I am so excited I cannot sit still
A4: contentment | B4: Mild, calm satisfaction | C4: Feeling calm and content
A5: pride | B5: Pleased with own or others' achievement | C5: Felt really proud of myself
A6: gratitude | B6: Thankful toward someone or something | C6: so grateful for her
A7: sadness | B7: Sadness, disappointment, loneliness, helplessness | C7: I am really sad
A8: anger | B8: Anger, frustration, irritation, betrayal | C8: I was furious
A9: fear | B9: Fear or anxiety about something specific or uncertain; panic | C9: Honestly scared
A10: stress | B10: General overload or pressure, not a specific threat | C10: Overwhelmed and cannot even think straight
A11: guilt | B11: Guilt, shame, embarrassment | C11: I feel so guilty
A12: surprise | B12: Surprised or shocked because something was unexpected | C12: Totally shocked
A13: neutral | B13: No feeling stated; a plain log of the day | C13: (no emotion clause)
A15: Tie-breakers
A16: fear vs stress | B16: Fear points at a specific threat or uncertainty. Stress is general overload.
A17: joy vs contentment | B17: Joy is energetic. Contentment is calm.
A18: sadness vs guilt | B18: Guilt involves something the writer did wrong or felt embarrassed about.
A19: surprise vs distress | B19: If the clause is mainly about something unexpected, use surprise. If it is mainly about distress, use the negative emotion.
A20: shocked, astonished, taken aback | B20: All map to surprise. There is no separate shocked label.
A22: Cause area (aspect)
A23: studies_work | B23: College, exams, assignments, jobs, interviews, projects
A24: health | B24: Fitness, sleep, illness, medical visits
A25: family | B25: Parents, siblings, relatives, home
A26: friends | B26: Friends, roommates, neighbours, classmates
A27: relationships | B27: Romantic partner
A28: self | B28: Habits, identity, motivation, memories, personal milestones
A29: money | B29: Rent, fees, stipend, bills, purchases
A30: other | B30: Commute, lost items, everyday events that fit nothing above
A31: none | B31: No cause stated, or cause is implicit
A33: Entity types (ner column, format text|TYPE separated by semicolons)
A34: PERSON | B34: Named people: Raj, Neha, Prof. Mehta
A35: ROLE | B35: A single person referred to by role or kinship: Mom, Dadi, My sister, my cousin, The doctor, Sir. Plural groups (my friends, relatives) are not tagged.
A36: LOCATION | B36: Named places only: Pune, Nagpur, US. Generic places (library, canteen, home, college) are not tagged.
A37: ORG | B37: Named organisations: TCS, Infosys, COEP. Generic words like college are not tagged.
A38: DATE | B38: Explicit time references: today, tonight, last night, this morning, Friday, March, next week. Bare words like morning or evening, and durations like two hours, are not tagged.
A39: none | B39: Write none when the entry has no entities. Blank always means not yet annotated.
A41: Row conventions
A42: Copy exactly | B42: emotion_clause, cause_clause and entity text are copied exactly from the entry, including typos.
A43: Implicit cause | B43: cause_clause = implicit, cause = unknown, aspect = none.
A44: Emotion only | B44: cause_clause left empty, cause = none, aspect = none.
...
